Workbook
Name AEDtoZAR: 'Inputs & Controls'!$B$5
Name Loan_Amount: '12M Cashflow Plan (2026)'!$C$97

Sheet Inputs & Controls
A2: Input | B2: Value | D2: Instructions
A3: Monthly Income (AED) | B3: 21100 | D3: • Adjust growth %, FX rate, and allocation sliders here.
A4: Base Monthly Expenses (AED) | B4: =Budget!C16 -> 13700 | D4: • Apartment/Other assets are placeholders; set when ready.
A5: ZAR per AED | B5: 4.66 | D5: • Projections & charts update from these inputs.
A6: Annual Income Growth % | B6: 2
A7: Annual Expense Inflation % | B7: 3
A8: Surplus Allocation to Debt (%) | B8: 70
A9: Surplus Allocation to Funds (%) | B9: 30
A10: Apartment Asset Value (AED) | B10: 0
A11: Other Assets (AED) | B11: 0
A12: Notes | B12: Adjust growth, allocations, and asset placeholders as needed.
A15: Goals & Funds
A16: Goal | B16: Target_AED | C16: Current_AED | D16: Progress_pct
A17: Emergency Fund | B17: 20000 | C17: 0 | D17: =IFERROR(C17/B17,0) -> 0
A18: Startup Seed Fund | B18: 25000 | C18: 0 | D18: =IFERROR(C18/B18,0) -> 0
A19: Political Development Fund | B19: 15000 | C19: 0 | D19: =IFERROR(C19/B19,0) -> 0

Sheet Dashboard
A1: Key KPIs | B1: Value
A3: Total Monthly Income (AED) | B3: ='Inputs & Controls'!B3 -> 21100
A4: Total Planned Expenses (AED) | B4: ='Inputs & Controls'!B4 -> 13700
A5: Planned Monthly Surplus (AED) | B5: =B3-B4 -> 7400
A6: Total Debt Outstanding (AED) | B6: =SUM('Assets and Liabilities'!E28:E34) -> 351764.13
A8: Assets (AED) | B8: ='Inputs & Controls'!B10 + 'Inputs & Controls'!B11 + SUM('Inputs & Controls'!C17:C19) -> 0
A9: Liabilities (AED) | B9: =B6 -> 351764.13
A10: Net Worth (AED) | B10: =B8-B9 -> -351764.13

Sheet Budget
B2: When I am on my own | F2: When I have support
B3: Category | C3: Monthly_AED | D3: Notes | F3: Category | G3: Monthly_AED | H3: Notes
B4: Rent (Dubai) | C4: 7500 | D4: 90k/year | F4: Food & Groceries | G4: =100*30 -> 3000
B5: Utilities + Internet + DEWA + Service Charges | C5: 1250 | D5: 15k/year | F5: Haircuts and Spa | G5: 800
B6: Food & Groceries | C6: 2000 | F6: Therapy or other extra-curriculars | G6: 1500
B7: Transport / Fuel / Metro | C7: 1000 | F7: Transport / Fuel / Metro | G7: 1000
B8: Insurance / Medical / Phone | C8: 500 | F8: Discretionary / Personal | G8: 700
B12: Haircuts and Coffee | C12: 750
B13: Discretionary / Personal | C13: 700
B16: Total Monthly Expenses | C16: =SUM(C4:C14) -> 13700 | F16: Total Monthly Expenses | G16: =SUM(G4:G14) -> 7000
B17: Family Support (R7,000) | C17: 1502.1459 | D17: R7k / ZAR per AED | F17: Family Support (R7,000) | G17: 1502.1459 | H17: R7k / ZAR per AED
B18: SA Debt Repayments (base plan) | C18: 3000 | D18: Target to clear in ~5 years | F18: SA Debt Repayments (base plan) | G18: 3000
B19: Savings / Emergency / Political + Business Funds | C19: 750 | F19: Savings / Emergency / Political + Business Funds | G19: 750
B20: SA Mortgage + Storage (split, R3,000) | C20: 643.77682 | D20: R3k / ZAR per AED | F20: SA Mortgage + Storage (split, R3,000) | G20: 643.77682 | H20: R3k / ZAR per AED
B21: Total Monthly Expenses (After Deductibles) | C21: =SUM(C16:C20) -> 19595.923 | F21: Total Monthly Expenses (After Deductibles) | G21: =SUM(G16:G20) -> 12895.923
B22: Remainder | C22: =C23-C21 -> 1504.0773 | F22: Remainder | G22: =G23-G21 -> 8204.0773
B23: Total Revenue | C23: ='Inputs & Controls'!B3 -> 21100 | F23: Total Revenue | G23: =C23 -> 21100

Sheet Assets and Liabilities
B3: Assets (AED)
B4: Lender | C4: Current Balance | D4: InterestRate_pct
B5: Emirates Debit | C5: 110400 | D5: 0.001
B6: Emirates Wealth | C6: 10000
B8: Assets (ZAR)
B9: Lender | C9: Current Balance | D9: InterestRate_pct
B10: Property | C10: 1300000
B11: FNB Fusion Account - Private Clients | C11: 16523
B12: FNB Debit | C12: 490
B13: Unamani FNB Debit | C13: 930
B15: ABSA Debit | C15: 13887.6
B16: Discovery Savings Account | C16: 62.26
B17: Discovery Black Debit | C17: 341.09
B18: Easy Equities | C18: 300
B20: Liabilities (AED)
B21: Lender | C21: Outstanding_AED | D21: InterestRate_pct | E21: Accessible Credit
B22: Emirates Credit Card | C22: 616.1 | D22: 0.22 | E22: =63000-C22 -> 62383.9
B26: Liabilities (ZAR)
B27: Lender | C27: Outstanding_ZAR | D27: InterestRate_pct | E27: Accessible Credit | G27: Rank_Priority
B28: Discovery Black Credit Card | C28: 0 | D28: 0.22 | E28: =67000-C28 -> 67000 | G28: 0
B29: ABSA Credit Card | C29: 35235.87 | D29: 0.205 | E29: =40000-C29 -> 4764.13 | G29: 2
B30: FNB Revolving Facility | C30: 0 | D30: 0.18 | E30: 210000 | G30: 0
B31: Father Investment Account | C31: 237944 | D31: 0 | E31: 0 | G31: 3
B32: Investment Account Loan | C32: 500000 | D32: 0.15 | E32: 0 | G32: 1
B33: Wits | C33: 35000 | D33: 0.22 | E33: 0 | G33: 0
B34: FNB Fusion Account - Private Clients | C34: 0 | D34: 0.18 | E34: =70000-C34 -> 70000 | G34: 0
B35: FNB Credit Card - Private Clients | C35: 246 | E35: =73500-C35 -> 73254
B36: FNB Private Client Home Loan | C36: 1358083 | D36: 0.11 | E36: 0 | G36: 0
B38: Total (ZAR) | C38: =SUM(C28:C36)-C36 -> 808425.87
B39: Total (AED) | C39: =C38/AEDtoZAR -> 173481.95
B40: Next Payable Account | C40: =INDEX($B$28:$B$36,MATCH(MAX($G$28:$G$36),$G$28:$G$36,0)) -> Father Investment Account
B41: Next Payable Amount (ZAR) | C41: =INDEX($C$28:$C$36,MATCH(C40,$B$28:$B$36,0)) -> 237944
B43: To Settle Credit Cards (ZAR) | C43: To Settle Credit Cards (AED) | D43: 50k AED in ZAR | E43: Remainder for Father | F43: Outstanding Owed Father | G43: Outstanding Owed Total
B44: =C38-C32-C31 -> 70481.87 | C44: =B44/AEDtoZAR -> 15124.865 | D44: =50000*AEDtoZAR -> 233000 | E44: =D44-B44 -> 162518.13 | F44: =C31-E44 -> 75425.87 | G44: =F44+C32 -> 575425.87
G45: =15000*12 -> 180000
B49: Description | C49: Date | D49: Paid | E49: Received
B50: First Payment | C50: 45982 | D50: =D44*0.5 -> 116500 | E50: =116500-206-450 -> 115844 | F50: =27000+79663 -> 106663 | G50: =E50-F50 -> 9181
B51: Second Payment | C51: =EDATE(C50,12) -> 46347 | D51: =D50 -> 116500

Sheet 12M Cashflow Plan (2026)
B2: Monthly Cashflows Projections
B3: Month | C3: Income_AED | D3: Monthly_Expenses_AED | E3: Family Support (R7,000) | F3: SA Debt Repayments (base plan) | G3: Savings / Emergency / Political + Business Funds | H3: SA Mortgage + Storage (split, R3,000) | I3: Total Monthly Expenses (After Deductibles) | J3: Surplus_AED
B4: 45962 | C4: ='Inputs & Controls'!$B$3 -> 21100 | D4: =3000 -> 3000 | E4: 0 | F4: 0 | G4: =Budget!$C$19 -> 750 | H4: =Budget!$C$20 -> 643.77682 | I4: =SUM(D4:H4) -> 4393.7768 | J4: =C4-I4 -> 16706.223
B5: =EDATE(B4,1) -> 45992 | C5: ='Inputs & Controls'!$B$3 -> 21100 | D5: 10000 | E5: =Budget!$C$17 -> 1502.1459 | F5: 3000 | G5: =Budget!$C$19 -> 750 | H5: =Budget!$C$20 -> 643.77682 | I5: =SUM(D5:H5) -> 15895.923 | J5: =C5-I5 -> 5204.0773
B6: =EDATE(B5,1) -> 46023 | C6: ='Inputs & Controls'!$B$3 -> 21100 | D6: =Budget!G16 -> 7000 | E6: =Budget!$C$17 -> 1502.1459 | F6: 3000 | G6: =Budget!$C$19 -> 750 | H6: =Budget!$C$20 -> 643.77682 | I6: =SUM(D6:H6) -> 12895.923 | J6: =C6-I6 -> 8204.0773
B7: =EDATE(B6,1) -> 46054 | C7: ='Inputs & Controls'!$B$3 -> 21100 | D7: =D6 -> 7000 | E7: =Budget!$C$17 -> 1502.1459 | F7: 3000 | G7: =Budget!$C$19 -> 750 | H7: =Budget!$C$20 -> 643.77682 | I7: =SUM(D7:H7) -> 12895.923 | J7: =C7-I7 -> 8204.0773
B8: =EDATE(B7,1) -> 46082 | C8: ='Inputs & Controls'!$B$3 -> 21100 | D8: =D7 -> 7000 | E8: =Budget!$C$17 -> 1502.1459 | F8: 3000 | G8: =Budget!$C$19 -> 750 | H8: =Budget!$C$20 -> 643.77682 | I8: =SUM(D8:H8) -> 12895.923 | J8: =C8-I8 -> 8204.0773
B9: =EDATE(B8,1) -> 46113 | C9: ='Inputs & Controls'!$B$3 -> 21100 | D9: =D8 -> 7000 | E9: =Budget!$C$17 -> 1502.1459 | F9: 3000 | G9: =Budget!$C$19 -> 750 | H9: =Budget!$C$20 -> 643.77682 | I9: =SUM(D9:H9) -> 12895.923 | J9: =C9-I9 -> 8204.0773
B10: =EDATE(B9,1) -> 46143 | C10: ='Inputs & Controls'!$B$3 -> 21100 | D10: =D9 -> 7000 | E10: =Budget!$C$17 -> 1502.1459 | F10: 3000 | G10: =Budget!$C$19 -> 750 | H10: =Budget!$C$20 -> 643.77682 | I10: =SUM(D10:H10) -> 12895.923 | J10: =C10-I10 -> 8204.0773
B11: =EDATE(B10,1) -> 46174 | C11: ='Inputs & Controls'!$B$3 -> 21100 | D11: =D10 -> 7000 | E11: =Budget!$C$17 -> 1502.1459 | F11: 3000 | G11: =Budget!$C$19 -> 750 | H11: =Budget!$C$20 -> 643.77682 | I11: =SUM(D11:H11) -> 12895.923 | J11: =C11-I11 -> 8204.0773
B12: =EDATE(B11,1) -> 46204 | C12: ='Inputs & Controls'!$B$3 -> 21100 | D12: =D11 -> 7000 | E12: =Budget!$C$17 -> 1502.1459 | F12: 3000 | G12: =Budget!$C$19 -> 750 | H12: =Budget!$C$20 -> 643.77682 | I12: =SUM(D12:H12) -> 12895.923 | J12: =C12-I12 -> 8204.0773
B13: =EDATE(B12,1) -> 46235 | C13: ='Inputs & Controls'!$B$3 -> 21100 | D13: ='Inputs & Controls'!$B$4 -> 13700 | E13: =Budget!$C$17 -> 1502.1459 | F13: 3000 | G13: =Budget!$C$19 -> 750 | H13: =Budget!$C$20 -> 643.77682 | I13: =SUM(D13:H13) -> 19595.923 | J13: =C13-I13 -> 1504.0773
B14: =EDATE(B13,1) -> 46266 | C14: ='Inputs & Controls'!$B$3 -> 21100 | D14: ='Inputs & Controls'!$B$4 -> 13700 | E14: =Budget!$C$17 -> 1502.1459 | F14: 3000 | G14: =Budget!$C$19 -> 750 | H14: =Budget!$C$20 -> 643.77682 | I14: =SUM(D14:H14) -> 19595.923 | J14: =C14-I14 -> 1504.0773
B15: =EDATE(B14,1) -> 46296 | C15: ='Inputs & Controls'!$B$3 -> 21100 | D15: ='Inputs & Controls'!$B$4 -> 13700 | E15: =Budget!$C$17 -> 1502.1459 | F15: 3000 | G15: =Budget!$C$19 -> 750 | H15: =Budget!$C$20 -> 643.77682 | I15: =SUM(D15:H15) -> 19595.923 | J15: =C15-I15 -> 1504.0773
B16: =EDATE(B15,1) -> 46327 | C16: ='Inputs & Controls'!$B$3 -> 21100 | D16: ='Inputs & Controls'!$B$4 -> 13700 | E16: =Budget!$C$17 -> 1502.1459 | F16: 3000 | G16: =Budget!$C$19 -> 750 | H16: =Budget!$C$20 -> 643.77682 | I16: =SUM(D16:H16) -> 19595.923 | J16: =C16-I16 -> 1504.0773
B17: =EDATE(B16,1) -> 46357 | C17: ='Inputs & Controls'!$B$3 -> 21100 | D17: ='Inputs & Controls'!$B$4 -> 13700 | E17: =Budget!$C$17 -> 1502.1459 | F17: 3000 | G17: =Budget!$C$19 -> 750 | H17: =Budget!$C$20 -> 643.77682 | I17: =SUM(D17:H17) -> 19595.923 | J17: =C17-I17 -> 1504.0773
B18: =EDATE(B17,1) -> 46388 | C18: ='Inputs & Controls'!$B$3 -> 21100 | D18: ='Inputs & Controls'!$B$4 -> 13700 | E18: =Budget!$C$17 -> 1502.1459 | F18: 3000 | G18: =Budget!$C$19 -> 750 | H18: =Budget!$C$20 -> 643.77682 | I18: =SUM(D18:H18) -> 19595.923 | J18: =C18-I18 -> 1504.0773
B19: =EDATE(B18,1) -> 46419 | C19: ='Inputs & Controls'!$B$3 -> 21100 | D19: ='Inputs & Controls'!$B$4 -> 13700 | E19: =Budget!$C$17 -> 1502.1459 | F19: 3000 | G19: =Budget!$C$19 -> 750 | H19: =Budget!$C$20 -> 643.77682 | I19: =SUM(D19:H19) -> 19595.923 | J19: =C19-I19 -> 1504.0773
B20: =EDATE(B19,1) -> 46447 | C20: ='Inputs & Controls'!$B$3 -> 21100 | D20: ='Inputs & Controls'!$B$4 -> 13700 | E20: =Budget!$C$17 -> 1502.1459 | F20: 3000 | G20: =Budget!$C$19 -> 750 | H20: =Budget!$C$20 -> 643.77682 | I20: =SUM(D20:H20) -> 19595.923 | J20: =C20-I20 -> 1504.0773
B21: =EDATE(B20,1) -> 46478 | C21: ='Inputs & Controls'!$B$3 -> 21100 | D21: ='Inputs & Controls'!$B$4 -> 13700 | E21: =Budget!$C$17 -> 1502.1459 | F21: 3000 | G21: =Budget!$C$19 -> 750 | H21: =Budget!$C$20 -> 643.77682 | I21: =SUM(D21:H21) -> 19595.923 | J21: =C21-I21 -> 1504.0773
B22: =EDATE(B21,1) -> 46508 | C22: ='Inputs & Controls'!$B$3 -> 21100 | D22: ='Inputs & Controls'!$B$4 -> 13700 | E22: =Budget!$C$17 -> 1502.1459 | F22: 3000 | G22: =Budget!$C$19 -> 750 | H22: =Budget!$C$20 -> 643.77682 | I22: =SUM(D22:H22) -> 19595.923 | J22: =C22-I22 -> 1504.0773
B23: =EDATE(B22,1) -> 46539 | C23: ='Inputs & Controls'!$B$3 -> 21100 | D23: ='Inputs & Controls'!$B$4 -> 13700 | E23: =Budget!$C$17 -> 1502.1459 | F23: 3000 | G23: =Budget!$C$19 -> 750 | H23: =Budget!$C$20 -> 643.77682 | I23: =SUM(D23:H23) -> 19595.923 | J23: =C23-I23 -> 1504.0773
B24: =EDATE(B23,1) -> 46569 | C24: ='Inputs & Controls'!$B$3 -> 21100 | D24: ='Inputs & Controls'!$B$4 -> 13700 | E24: =Budget!$C$17 -> 1502.1459 | F24: 3000 | G24: =Budget!$C$19 -> 750 | H24: =Budget!$C$20 -> 643.77682 | I24: =SUM(D24:H24) -> 19595.923 | J24: =C24-I24 -> 1504.0773
... B30: =EDATE(B29,1) -> 46753 | C30: ='Inputs & Controls'!$B$3 -> 21100 | D30: ='Inputs & Controls'!$B$4 -> 13700 | E30: =Budget!$C$17 -> 1502.1459 | F30: 3000 | G30: =Budget!$C$19 -> 750 | H30: =Budget!$C$20 -> 643.77682 | I30: =SUM(D30:H30) -> 19595.923 | J30: =C30-I30 -> 1504.0773
B32: Debt and Savings Balance Projections
B33: Month | C33: Outstanding Debt Balance | D33: ='Inputs & Controls'!A17 -> Emergency Fund | E33: ='Inputs & Controls'!A18 -> Startup Seed Fund | F33: ='Inputs & Controls'!A19 -> Political Development Fund | G33: Family Support (R7,000) | H33: SA Mortgage
B34: =B4 -> 45962 | C34: ='Assets and Liabilities'!C38-'Assets and Liabilities'!B44 -> 737944 | D34: =$G$4/3 -> 250 | E34: =$G$4/3 -> 250 | F34: =$G$4/3 -> 250 | G34: =E4*AEDtoZAR -> 0 | H34: ='Assets and Liabilities'!C36-13000 -> 1345083
B35: =B5 -> 45992 | C35: =C34-(F5*AEDtoZAR) -> 723964 | D35: =D34+G5/3 -> 500 | E35: =E34+G5/3 -> 500 | F35: =F34+G5/3 -> 500 | G35: =G34+E5*AEDtoZAR -> 7000 | H35: =H34-13000 -> 1332083
B36: =B6 -> 46023 | C36: =C35-(F6*AEDtoZAR) -> 709984 | D36: =D35+G6/3 -> 750 | E36: =E35+G6/3 -> 750 | F36: =F35+G6/3 -> 750 | G36: =G35+E6*AEDtoZAR -> 14000 | H36: =H35-13000 -> 1319083
B37: =B7 -> 46054 | C37: =C36-(F7*AEDtoZAR) -> 696004 | D37: =D36+G7/3 -> 1000 | E37: =E36+G7/3 -> 1000 | F37: =F36+G7/3 -> 1000 | G37: =G36+E7*AEDtoZAR -> 21000 | H37: =H36-13000 -> 1306083
B38: =B8 -> 46082 | C38: =C37-(F8*AEDtoZAR) -> 682024 | D38: =D37+G8/3 -> 1250 | E38: =E37+G8/3 -> 1250 | F38: =F37+G8/3 -> 1250 | G38: =G37+E8*AEDtoZAR -> 28000 | H38: =H37-13000 -> 1293083
B39: =B9 -> 46113 | C39: =C38-(F9*AEDtoZAR) -> 668044 | D39: =D38+G9/3 -> 1500 | E39: =E38+G9/3 -> 1500 | F39: =F38+G9/3 -> 1500 | G39: =G38+E9*AEDtoZAR -> 35000 | H39: =H38-13000 -> 1280083
B40: =B10 -> 46143 | C40: =C39-(F10*AEDtoZAR) -> 654064 | D40: =D39+G10/3 -> 1750 | E40: =E39+G10/3 -> 1750 | F40: =F39+G10/3 -> 1750 | G40: =G39+E10*AEDtoZAR -> 42000 | H40: =H39-13000 -> 1267083
B41: =B11 -> 46174 | C41: =C40-(F11*AEDtoZAR) -> 640084 | D41: =D40+G11/3 -> 2000 | E41: =E40+G11/3 -> 2000 | F41: =F40+G11/3 -> 2000 | G41: =G40+E11*AEDtoZAR -> 49000 | H41: =H40-13000 -> 1254083
B42: =B12 -> 46204 | C42: =C41-(F12*AEDtoZAR) -> 626104 | D42: =D41+G12/3 -> 2250 | E42: =E41+G12/3 -> 2250 | F42: =F41+G12/3 -> 2250 | G42: =G41+E12*AEDtoZAR -> 56000 | H42: =H41-13000 -> 1241083
B43: =B13 -> 46235 | C43: =C42-(F13*AEDtoZAR) -> 612124 | D43: =D42+G13/3 -> 2500 | E43: =E42+G13/3 -> 2500 | F43: =F42+G13/3 -> 2500 | G43: =G42+E13*AEDtoZAR -> 63000 | H43: =H42-13000 -> 1228083
B44: =B14 -> 46266 | C44: =C43-(F14*AEDtoZAR) -> 598144 | D44: =D43+G14/3 -> 2750 | E44: =E43+G14/3 -> 2750 | F44: =F43+G14/3 -> 2750 | G44: =G43+E14*AEDtoZAR -> 70000 | H44: =H43-13000 -> 1215083
B45: =B15 -> 46296 | C45: =C44-(F15*AEDtoZAR) -> 584164 | D45: =D44+G15/3 -> 3000 | E45: =E44+G15/3 -> 3000 | F45: =F44+G15/3 -> 3000 | G45: =G44+E15*AEDtoZAR -> 77000 | H45: =H44-13000 -> 1202083
B46: =B16 -> 46327 | C46: =C45-(F16*AEDtoZAR) -> 570184 | D46: =D45+G16/3 -> 3250 | E46: =E45+G16/3 -> 3250 | F46: =F45+G16/3 -> 3250 | G46: =G45+E16*AEDtoZAR -> 84000 | H46: =H45-13000 -> 1189083
... B55: =B25 -> 46600 | C55: =C54-(F25*AEDtoZAR) -> 444364 | D55: =D54+G25/3 -> 5500 | E55: =E54+G25/3 -> 5500 | F55: =F54+G25/3 -> 5500 | G55: =G54+E25*AEDtoZAR -> 147000 | H55: =H54-13000 -> 1072083
...

Sheet Total Paid in Family Support
B2: Total Paid in Family Support
B3: Date | C3: Monthly Payment | D3: Mother Split | E3: Father Split | F3: Phone and insurance | G3: Total Monthly Family Support | H3: Total Paid in Family Support
B4: 44197 | C4: 10000 | D4: =C4-SUM(E4:F4) -> 8200 | E4: 0 | F4: =1000+800 -> 1800 | G4: =C4-F4 -> 8200 | H4: =G4 -> 8200 | I4: * Paid whilst still living at Bon Accord
B5: =EDATE(B4,1) -> 44228 | C5: 10000 | D5: =C5-SUM(E5:F5) -> 8200 | E5: 0 | F5: =1000+800 -> 1800 | G5: =C5-F5 -> 8200 | H5: =H4+G5 -> 16400
B6: =EDATE(B5,1) -> 44256 | C6: 10000 | D6: =C6-SUM(E6:F6) -> 8200 | E6: 0 | F6: =1000+800 -> 1800 | G6: =C6-F6 -> 8200 | H6: =H5+G6 -> 24600
B7: =EDATE(B6,1) -> 44287 | C7: 10000 | D7: =C7-SUM(E7:F7) -> 8200 | E7: 0 | F7: =1000+800 -> 1800 | G7: =C7-F7 -> 8200 | H7: =H6+G7 -> 32800
B8: =EDATE(B7,1) -> 44317 | C8: 10000 | D8: =C8-SUM(E8:F8) -> 8200 | E8: 0 | F8: =1000+800 -> 1800 | G8: =C8-F8 -> 8200 | H8: =H7+G8 -> 41000
B9: =EDATE(B8,1) -> 44348 | C9: 10000 | D9: =C9-SUM(E9:F9) -> 8200 | E9: 0 | F9: =1000+800 -> 1800 | G9: =C9-F9 -> 8200 | H9: =H8+G9 -> 49200
B10: =EDATE(B9,1) -> 44378 | C10: 10000 | D10: =C10-SUM(E10:F10) -> 8200 | E10: 0 | F10: =1000+800 -> 1800 | G10: =C10-F10 -> 8200 | H10: =H9+G10 -> 57400
B11: =EDATE(B10,1) -> 44409 | C11: 10000 | D11: =C11-SUM(E11:F11) -> 8200 | E11: 0 | F11: =1000+800 -> 1800 | G11: =C11-F11 -> 8200 | H11: =H10+G11 -> 65600
B12: =EDATE(B11,1) -> 44440 | C12: 10000 | D12: =C12-SUM(E12:F12) -> 8200 | E12: 0 | F12: =1000+800 -> 1800 | G12: =C12-F12 -> 8200 | H12: =H11+G12 -> 73800
B13: =EDATE(B12,1) -> 44470 | C13: 10000 | D13: =C13-SUM(E13:F13) -> 8200 | E13: 0 | F13: =1000+800 -> 1800 | G13: =C13-F13 -> 8200 | H13: =H12+G13 -> 82000
B14: =EDATE(B13,1) -> 44501 | C14: =6500 -> 6500 | D14: =C14-SUM(E14:F14) -> 3200 | E14: 1500 | F14: =1000+800 -> 1800 | G14: =C14-F14 -> 4700 | H14: =H13+G14 -> 86700 | I14: * Started splitting the amount to cover father asking for money (R50 per day for 30 days)
B15: =EDATE(B14,1) -> 44531 | C15: =6500 -> 6500 | D15: =C15-SUM(E15:F15) -> 3200 | E15: 1500 | F15: =1000+800 -> 1800 | G15: =C15-F15 -> 4700 | H15: =H14+G15 -> 91400
B16: =EDATE(B15,1) -> 44562 | C16: =6500 -> 6500 | D16: =C16-SUM(E16:F16) -> 3200 | E16: 1500 | F16: =1000+800 -> 1800 | G16: =C16-F16 -> 4700 | H16: =H15+G16 -> 96100
B17: =EDATE(B16,1) -> 44593 | C17: =6500 -> 6500 | D17: =C17-SUM(E17:F17) -> 3200 | E17: 1500 | F17: =1000+800 -> 1800 | G17: =C17-F17 -> 4700 | H17: =H16+G17 -> 100800
B18: =EDATE(B17,1) -> 44621 | C18: =6500 -> 6500 | D18: =C18-SUM(E18:F18) -> 3200 | E18: 1500 | F18: =1000+800 -> 1800 | G18: =C18-F18 -> 4700 | H18: =H17+G18 -> 105500
B19: =EDATE(B18,1) -> 44652 | C19: =6500 -> 6500 | D19: =C19-SUM(E19:F19) -> 2100 | E19: 1500 | F19: =1100+1800 -> 2900 | G19: =C19-F19 -> 3600 | H19: =H18+G19 -> 109100 | I19: * Purchased BMW and upgraded phone
B20: =EDATE(B19,1) -> 44682 | C20: =6500 -> 6500 | D20: =C20-SUM(E20:F20) -> 2100 | E20: 1500 | F20: =1100+1800 -> 2900 | G20: =C20-F20 -> 3600 | H20: =H19+G20 -> 112700
B21: =EDATE(B20,1) -> 44713 | C21: =6500 -> 6500 | D21: =C21-SUM(E21:F21) -> 2100 | E21: 1500 | F21: =1100+1800 -> 2900 | G21: =C21-F21 -> 3600 | H21: =H20+G21 -> 116300
B22: =EDATE(B21,1) -> 44743 | C22: =6500 -> 6500 | D22: =C22-SUM(E22:F22) -> 2100 | E22: 1500 | F22: =1100+1800 -> 2900 | G22: =C22-F22 -> 3600 | H22: =H21+G22 -> 119900
B23: =EDATE(B22,1) -> 44774 | C23: =6500 -> 6500 | D23: =C23-SUM(E23:F23) -> 2100 | E23: 1500 | F23: =1100+1800 -> 2900 | G23: =C23-F23 -> 3600 | H23: =H22+G23 -> 123500
B24: =EDATE(B23,1) -> 44805 | C24: =6500 -> 6500 | D24: =C24-SUM(E24:F24) -> 2100 | E24: 1500 | F24: =1100+1800 -> 2900 | G24: =C24-F24 -> 3600 | H24: =H23+G24 -> 127100
B25: =EDATE(B24,1) -> 44835 | C25: =6500 -> 6500 | D25: =C25-SUM(E25:F25) -> 2100 | E25: 1500 | F25: =1100+1800 -> 2900 | G25: =C25-F25 -> 3600 | H25: =H24+G25 -> 130700
B26: =EDATE(B25,1) -> 44866 | C26: =6500 -> 6500 | D26: =C26-SUM(E26:F26) -> 2100 | E26: 1500 | F26: =1100+1800 -> 2900 | G26: =C26-F26 -> 3600 | H26: =H25+G26 -> 134300
B27: =EDATE(B26,1) -> 44896 | C27: =6500 -> 6500 | D27: =C27-SUM(E27:F27) -> 2100 | E27: 1500 | F27: =1100+1800 -> 2900 | G27: =C27-F27 -> 3600 | H27: =H26+G27 -> 137900
B28: =EDATE(B27,1) -> 44927 | C28: =6500 -> 6500 | D28: =C28-SUM(E28:F28) -> 2100 | E28: 1500 | F28: =1100+1800 -> 2900 | G28: =C28-F28 -> 3600 | H28: =H27+G28 -> 141500
B29: =EDATE(B28,1) -> 44958 | C29: =6500 -> 6500 | D29: =C29-SUM(E29:F29) -> 2100 | E29: 1500 | F29: =1100+1800 -> 2900 | G29: =C29-F29 -> 3600 | H29: =H28+G29 -> 145100
B30: =EDATE(B29,1) -> 44986 | C30: =6500 -> 6500 | D30: =C30-SUM(E30:F30) -> 2100 | E30: 1500 | F30: =1100+1800 -> 2900 | G30: =C30-F30 -> 3600 | H30: =H29+G30 -> 148700
B31: =EDATE(B30,1) -> 45017 | C31: =6500 -> 6500 | D31: =C31-SUM(E31:F31) -> 2100 | E31: 1500 | F31: =1100+1800 -> 2900 | G31: =C31-F31 -> 3600 | H31: =H30+G31 -> 152300
... B46: =EDATE(B45,1) -> 45474 | C46: =6500 -> 6500 | D46: =C46-SUM(E46:F46) -> 2100 | E46: 1500 | F46: =1100+1800 -> 2900 | G46: =C46-F46 -> 3600 | H46: =H45+G46 -> 206300
B47: =EDATE(B46,1) -> 45505 | C47: =6500 -> 6500 | D47: =C47-SUM(E47:F47) -> 3600 | E47: 0 | F47: =1100+1800 -> 2900 | G47: =C47-F47 -> 3600 | H47: =H46+G47 -> 209900 | I47: * Father went to Rehab
B48: =EDATE(B47,1) -> 45536 | C48: =6500 -> 6500 | D48: =C48-SUM(E48:F48) -> 3600 | E48: 0 | F48: =1100+1800 -> 2900 | G48: =C48-F48 -> 3600 | H48: =H47+G48 -> 213500
B49: =EDATE(B48,1) -> 45566 | C49: =6500 -> 6500 | D49: =C49-SUM(E49:F49) -> 3600 | E49: 0 | F49: =1100+1800 -> 2900 | G49: =C49-F49 -> 3600 | H49: =H48+G49 -> 217100
B50: =EDATE(B49,1) -> 45597 | C50: =6500 -> 6500 | D50: =C50-SUM(E50:F50) -> 3600 | E50: 0 | F50: =1100+1800 -> 2900 | G50: =C50-F50 -> 3600 | H50: =H49+G50 -> 220700
B51: =EDATE(B50,1) -> 45627 | C51: =6500 -> 6500 | D51: =C51-SUM(E51:F51) -> 3600 | E51: 0 | F51: =1100+1800 -> 2900 | G51: =C51-F51 -> 3600 | H51: =H50+G51 -> 224300
B52: =EDATE(B51,1) -> 45658 | C52: =6500 -> 6500 | D52: =C52-SUM(E52:F52) -> 3600 | E52: 0 | F52: =1100+1800 -> 2900 | G52: =C52-F52 -> 3600 | H52: =H51+G52 -> 227900
B53: =EDATE(B52,1) -> 45689 | C53: =6500 -> 6500 | D53: =C53-SUM(E53:F53) -> 3600 | E53: 0 | F53: =1100+1800 -> 2900 | G53: =C53-F53 -> 3600 | H53: =H52+G53 -> 231500
B54: =EDATE(B53,1) -> 45717 | C54: =6500 -> 6500 | D54: =C54-SUM(E54:F54) -> 3600 | E54: 0 | F54: =1100+1800 -> 2900 | G54: =C54-F54 -> 3600 | H54: =H53+G54 -> 235100
B55: =EDATE(B54,1) -> 45748 | C55: =6500 -> 6500 | D55: =C55-SUM(E55:F55) -> 3600 | E55: 0 | F55: =1100+1800 -> 2900 | G55: =C55-F55 -> 3600 | H55: =H54+G55 -> 238700
...

Sheet Transactions (Template)
A1: Date | B1: Description | C1: Amount | D1: Currency | E1: Category | F1: Account | G1: Bank | H1: Type | I1: Notes
